<?xml version="1.0"?>
<robot xmlns:xacro="http://wiki.ros.org/xacro">

  <xacro:macro name="kuka_kr120r2500pro" params="prefix">
    <!-- LINKS -->
    <!-- base link -->
    <link name="${prefix}base_link">
      <inertial>
        <origin xyz="0 0 0" rpy="0 0 0"/>
        <mass value="300"/>
        <inertia ixx="18" ixy="-0.01" ixz="0.17562" iyy="20.51" iyz="0.0017576" izz="35.02"/>
      </inertial>
      <visual>
        <origin xyz="0 0 0" rpy="0 0 0"/>
        <geometry>
          <mesh filename="package://kuka_kr120_support/meshes/kr120r2500pro/visual/base_link.dae" />
        </geometry>
      </visual>
      <collision>
        <origin xyz="0 0 0" rpy="0 0 0"/>
        <geometry>
          <mesh filename="package://kuka_kr120_support/meshes/kr120r2500pro/collision/base_link.stl" />
        </geometry>
      </collision>
    </link>
    <!-- link 1 (A1) -->
    <link name="${prefix}link_1">
      <inertial>
        <origin xyz="0 0 0" rpy="0 0 0"/>
        <mass value="277.5"/>
        <inertia ixx="18" ixy="6.6" ixz="3.2" iyy="29.4" iyz="0.013634" izz="33.605"/>
      </inertial>
      <visual>
        <origin xyz="0 0 0" rpy="0 0 0"/>
        <geometry>
          <mesh filename="package://kuka_kr120_support/meshes/kr120r2500pro/visual/link_1.dae" />
        </geometry>
      </visual>
      <collision>
        <origin xyz="0 0 0" rpy="0 0 0"/>
        <geometry>
          <mesh filename="package://kuka_kr120_support/meshes/kr120r2500pro/collision/link_1.stl" />
        </geometry>
      </collision>
    </link>
    <!-- link 2 -->
    <link name="${prefix}link_2">
      <inertial>
        <origin xyz="0 0 0" rpy="0 0 0"/>
        <mass value="191.6"/>
        <inertia ixx="36.5" ixy="-0.163462" ixz="0.06549" iyy="35.68" iyz="-4.82" izz="4.495"/>
      </inertial>
      <visual>
        <origin xyz="0 0 0" rpy="0 0 0"/>
        <geometry>
          <mesh filename="package://kuka_kr120_support/meshes/kr120r2500pro/visual/link_2.dae"/>
        </geometry>
      </visual>
      <collision>
        <origin xyz="0 0 0" rpy="0 0 0"/>
        <geometry>
          <mesh filename="package://kuka_kr120_support/meshes/kr120r2500pro/collision/link_2.stl" />
        </geometry>
      </collision>
    </link>
    <!-- link 3 -->
    <link name="${prefix}link_3">
      <inertial>
        <origin xyz="0 0 0" rpy="0 0 0"/>
        <mass value="142.03"/>
        <inertia ixx="2.887" ixy="-0.02154" ixz="-0.2604" iyy="19.805" iyz="-0.016505" izz="19.251"/>
      </inertial>
      <visual>
        <origin xyz="0 0 0" rpy="0 0 0"/>
        <geometry>
          <mesh filename="package://kuka_kr120_support/meshes/kr120r2500pro/visual/link_3.dae" />
        </geometry>
      </visual>
      <collision>
        <origin xyz="0 0 0" rpy="0 0 0"/>
        <geometry>
          <mesh filename="package://kuka_kr120_support/meshes/kr120r2500pro/collision/link_3.stl" />
        </geometry>
      </collision>
    </link>
    <!-- link 4 -->
    <link name="${prefix}link_4">
      <inertial>
        <origin xyz="0 0 0" rpy="0 0 0"/>
        <mass value="34.73"/>
        <inertia ixx="0.36001" ixy="-0.36515" ixz="0.00011232" iyy="1.114" iyz="0.00050469" izz="1.3498"/>
      </inertial>
      <visual>
        <origin xyz="0 0 0" rpy="0 0 0"/>
        <geometry>
          <mesh filename="package://kuka_kr120_support/meshes/kr120r2500pro/visual/link_4.dae" />
        </geometry>
      </visual>
      <collision>
        <origin xyz="0 0 0" rpy="0 0 0"/>
        <geometry>
          <mesh filename="package://kuka_kr120_support/meshes/kr120r2500pro/collision/link_4.stl" />
        </geometry>
      </collision>
    </link>
    <!-- link 5 -->
    <link name="${prefix}link_5">
      <inertial>
        <origin xyz="0 0 0" rpy="0 0 0"/>
        <mass value="25.17"/>
        <inertia ixx="0.0838" ixy="-0.0165332" ixz="1.7223E-06" iyy="0.12945" iyz="-7.0292E-06" izz="0.12292"/>
      </inertial>
      <visual>
        <origin xyz="0 0 0" rpy="0 0 0"/>
        <geometry>
          <mesh filename="package://kuka_kr120_support/meshes/kr120r2500pro/visual/link_5.dae" />
        </geometry>
      </visual>
      <collision>
        <origin xyz="0 0 0" rpy="0 0 0"/>
        <geometry>
          <mesh filename="package://kuka_kr120_support/meshes/kr120r2500pro/collision/link_5.stl" />
        </geometry>
      </collision>
    </link>
    <!-- link 6 -->
    <link name="${prefix}link_6">
      <inertial>
        <origin xyz="0 0 0" rpy="0 0 0"/>
        <mass value="6.3154"/>
        <inertia ixx="0.031746" ixy="1.7673E-07" ixz="-6.6558E-06" iyy="0.016686" iyz="1.4304E-07" izz="0.016723"/>
      </inertial>
      <visual>
        <origin xyz="0 0 0" rpy="0 0 0"/>
        <geometry>
          <mesh filename="package://kuka_kr120_support/meshes/kr120r2500pro/visual/link_6.dae" />
        </geometry>
      </visual>
      <collision>
        <origin xyz="0 0 0" rpy="0 0 0"/>
        <geometry>
          <mesh filename="package://kuka_kr120_support/meshes/kr120r2500pro/collision/link_6.stl" />
        </geometry>
      </collision>
    </link>
    <!-- Following REP199, this frame shall be use to attach EEF or other equipment -->
    <link name="${prefix}flange" />
    <!-- END LINKS -->

    <!-- JOINTS -->
    <!-- joint 1 (A1) -->
    <joint name="${prefix}joint_a1" type="revolute">
      <origin xyz="0 0 0.675" rpy="0 0 0"/>
      <parent link="${prefix}base_link"/>
      <child link="${prefix}link_1"/>
      <axis xyz="0 0 -1"/>
      <limit effort="1000" lower="${-radians(185)}" upper="${radians(185)}" velocity="${radians(156)}"/>
    </joint>
    <!-- joint 2 (A2) -->
    <joint name="${prefix}joint_a2" type="revolute">
      <origin xyz="0.35 0 0" rpy="0 0 0"/>
      <parent link="${prefix}link_1"/>
      <child link="${prefix}link_2"/>
      <axis xyz="0 1 0"/>
      <limit effort="1000" lower="${-radians(65)}" upper="${radians(125)}" velocity="${radians(156)}"/>
    </joint>
    <!-- joint 3 (A3) -->
    <joint name="${prefix}joint_a3" type="revolute">
      <origin xyz="1.150 0 0" rpy="0 0 0"/>
      <parent link="${prefix}link_2"/>
      <child link="${prefix}link_3"/>
      <axis xyz="0 1 0"/>
      <limit effort="1000" lower="${-radians(220)}" upper="${radians(64)}" velocity="${radians(156)}"/>
    </joint>
    <!-- joint 4 (A4) -->
    <joint name="${prefix}joint_a4" type="revolute">
      <origin xyz="1.0 0 -0.041" rpy="0 0 0"/>
      <parent link="${prefix}link_3"/>
      <child link="${prefix}link_4"/>
      <axis xyz="-1 0 0"/>
      <limit effort="1000" lower="${-radians(350)}" upper="${radians(350)}" velocity="${radians(330)}"/>
    </joint>
    <!-- joint 5 (A5) -->
    <joint name="${prefix}joint_a5" type="revolute">
      <origin xyz="0 0 0" rpy="0 0 0"/>
      <parent link="${prefix}link_4"/>
      <child link="${prefix}link_5"/>
      <axis xyz="0 1 0"/>
      <limit effort="1000" lower="${-radians(130)}" upper="${radians(130)}" velocity="${radians(330)}"/>
    </joint>
    <!-- joint 6 (A6) -->
    <joint name="${prefix}joint_a6" type="revolute">
      <origin xyz="0 0 0" rpy="0 0 0"/>
      <parent link="${prefix}link_5"/>
      <child link="${prefix}link_6"/>
      <axis xyz="-1 0 0"/>
      <limit effort="1000" lower="${-radians(350)}" upper="${radians(350)}" velocity="${radians(615)}"/>
    </joint>
    <!-- tool frame - fixed frame -->
    <joint name="${prefix}joint_a6-flange" type="fixed">
      <parent link="${prefix}link_6"/>
      <child link="${prefix}flange"/>
      <origin xyz="0.215 0 0" rpy="0 0 0"/>
    </joint>
    <!-- END JOINTS -->

    <!-- ROS base_link to KUKA $ROBROOT coordinate system transform -->
    <link name="${prefix}base" />
    <joint name="${prefix}base_link-base" type="fixed">
      <origin xyz="0 0 0" rpy="0 0 0"/>
      <parent link="${prefix}base_link"/>
      <child link="${prefix}base"/>
    </joint>

    <!-- This frame corresponds to the $TOOL coordinate system in KUKA KRC controllers -->
    <link name="${prefix}tool0" />
    <joint name="${prefix}flange-tool0" type="fixed">
      <parent link="${prefix}flange"/>
      <child link="${prefix}tool0"/>
      <origin xyz="0 0 0" rpy="0 ${radians(90)} 0"/>
    </joint>
  </xacro:macro>
</robot>


